[2022-12-02T20:39:01.875+0000] {taskinstance.py:1165} INFO - Dependencies all met for <TaskInstance: extract_dag.extract_weather_api scheduled__2022-12-02T20:15:00+00:00 [queued]>
[2022-12-02T20:39:01.885+0000] {taskinstance.py:1165} INFO - Dependencies all met for <TaskInstance: extract_dag.extract_weather_api scheduled__2022-12-02T20:15:00+00:00 [queued]>
[2022-12-02T20:39:01.888+0000] {taskinstance.py:1362} INFO - 
--------------------------------------------------------------------------------
[2022-12-02T20:39:01.889+0000] {taskinstance.py:1363} INFO - Starting attempt 1 of 2
[2022-12-02T20:39:01.890+0000] {taskinstance.py:1364} INFO - 
--------------------------------------------------------------------------------
[2022-12-02T20:39:01.899+0000] {taskinstance.py:1383} INFO - Executing <Task(BashOperator): extract_weather_api> on 2022-12-02 20:15:00+00:00
[2022-12-02T20:39:01.904+0000] {standard_task_runner.py:55} INFO - Started process 3753 to run task
[2022-12-02T20:39:01.907+0000] {standard_task_runner.py:82} INFO - Running: ['***', 'tasks', 'run', 'extract_dag', 'extract_weather_api', 'scheduled__2022-12-02T20:15:00+00:00', '--job-id', '3', '--raw', '--subdir', 'DAGS_FOLDER/extract_dag.py', '--cfg-path', '/tmp/tmpgzz838kh']
[2022-12-02T20:39:01.908+0000] {standard_task_runner.py:83} INFO - Job 3: Subtask extract_weather_api
[2022-12-02T20:39:01.946+0000] {task_command.py:376} INFO - Running <TaskInstance: extract_dag.extract_weather_api scheduled__2022-12-02T20:15:00+00:00 [running]> on host 94f969375df6
[2022-12-02T20:39:01.982+0000] {taskinstance.py:1592} INFO - Exporting the following env vars:
AIRFLOW_CTX_DAG_EMAIL=***@***.com
AIRFLOW_CTX_DAG_OWNER=***
AIRFLOW_CTX_DAG_ID=extract_dag
AIRFLOW_CTX_TASK_ID=extract_weather_api
AIRFLOW_CTX_EXECUTION_DATE=2022-12-02T20:15:00+00:00
AIRFLOW_CTX_TRY_NUMBER=1
AIRFLOW_CTX_DAG_RUN_ID=scheduled__2022-12-02T20:15:00+00:00
[2022-12-02T20:39:01.985+0000] {subprocess.py:63} INFO - Tmp dir root location: 
 /tmp
[2022-12-02T20:39:01.986+0000] {subprocess.py:75} INFO - Running command: ['/bin/bash', '-c', 'python /Users/gagandeepkundi/data-engineering/projects/weather-etl-ml-project/src/extract.py']
[2022-12-02T20:39:01.998+0000] {subprocess.py:86} INFO - Output:
[2022-12-02T20:39:02.059+0000] {subprocess.py:93} INFO - python: can't open file '/Users/gagandeepkundi/data-engineering/projects/weather-etl-ml-project/src/extract.py': [Errno 2] No such file or directory
[2022-12-02T20:39:02.061+0000] {subprocess.py:97} INFO - Command exited with return code 2
[2022-12-02T20:39:02.070+0000] {taskinstance.py:1851} ERROR - Task failed with exception
Traceback (most recent call last):
  File "/home/airflow/.local/lib/python3.7/site-packages/airflow/operators/bash.py", line 197, in execute
    f'Bash command failed. The command returned a non-zero exit code {result.exit_code}.'
airflow.exceptions.AirflowException: Bash command failed. The command returned a non-zero exit code 2.
[2022-12-02T20:39:02.073+0000] {taskinstance.py:1406} INFO - Marking task as UP_FOR_RETRY. dag_id=extract_dag, task_id=extract_weather_api, execution_date=20221202T201500, start_date=20221202T203901, end_date=20221202T203902
[2022-12-02T20:39:02.081+0000] {standard_task_runner.py:105} ERROR - Failed to execute job 3 for task extract_weather_api (Bash command failed. The command returned a non-zero exit code 2.; 3753)
[2022-12-02T20:39:02.121+0000] {local_task_job.py:164} INFO - Task exited with return code 1
[2022-12-02T20:39:02.135+0000] {local_task_job.py:273} INFO - 0 downstream tasks scheduled from follow-on schedule check
[2022-12-04T00:39:23.303+0000] {taskinstance.py:1165} INFO - Dependencies all met for <TaskInstance: extract_dag.extract_weather_api scheduled__2022-12-02T20:15:00+00:00 [queued]>
[2022-12-04T00:39:23.312+0000] {taskinstance.py:1165} INFO - Dependencies all met for <TaskInstance: extract_dag.extract_weather_api scheduled__2022-12-02T20:15:00+00:00 [queued]>
[2022-12-04T00:39:23.313+0000] {taskinstance.py:1362} INFO - 
--------------------------------------------------------------------------------
[2022-12-04T00:39:23.314+0000] {taskinstance.py:1363} INFO - Starting attempt 1 of 1
[2022-12-04T00:39:23.314+0000] {taskinstance.py:1364} INFO - 
--------------------------------------------------------------------------------
[2022-12-04T00:39:23.326+0000] {taskinstance.py:1383} INFO - Executing <Task(PythonOperator): extract_weather_api> on 2022-12-02 20:15:00+00:00
[2022-12-04T00:39:23.337+0000] {standard_task_runner.py:55} INFO - Started process 60 to run task
[2022-12-04T00:39:23.342+0000] {standard_task_runner.py:82} INFO - Running: ['***', 'tasks', 'run', 'extract_dag', 'extract_weather_api', 'scheduled__2022-12-02T20:15:00+00:00', '--job-id', '10', '--raw', '--subdir', 'DAGS_FOLDER/extract_dag.py', '--cfg-path', '/tmp/tmpa0mg7bli']
[2022-12-04T00:39:23.345+0000] {standard_task_runner.py:83} INFO - Job 10: Subtask extract_weather_api
[2022-12-04T00:39:23.429+0000] {task_command.py:376} INFO - Running <TaskInstance: extract_dag.extract_weather_api scheduled__2022-12-02T20:15:00+00:00 [running]> on host 65ab33c03c57
[2022-12-04T00:39:23.485+0000] {taskinstance.py:1592} INFO - Exporting the following env vars:
AIRFLOW_CTX_DAG_EMAIL=***@***.com
AIRFLOW_CTX_DAG_OWNER=***
AIRFLOW_CTX_DAG_ID=extract_dag
AIRFLOW_CTX_TASK_ID=extract_weather_api
AIRFLOW_CTX_EXECUTION_DATE=2022-12-02T20:15:00+00:00
AIRFLOW_CTX_TRY_NUMBER=1
AIRFLOW_CTX_DAG_RUN_ID=scheduled__2022-12-02T20:15:00+00:00
[2022-12-04T00:39:23.864+0000] {taskinstance.py:1851} ERROR - Task failed with exception
Traceback (most recent call last):
  File "/home/airflow/.local/lib/python3.7/site-packages/airflow/operators/python.py", line 175, in execute
    return_value = self.execute_callable()
  File "/home/airflow/.local/lib/python3.7/site-packages/airflow/operators/python.py", line 193, in execute_callable
    return self.python_callable(*self.op_args, **self.op_kwargs)
  File "/opt/airflow/dags/extract_dag.py", line 37, in extract_func
    df.to_csv(f'/usr/local/airflow/data/{col_name}_weather_api.csv',index=False)
  File "/home/airflow/.local/lib/python3.7/site-packages/pandas/core/generic.py", line 3482, in to_csv
    storage_options=storage_options,
  File "/home/airflow/.local/lib/python3.7/site-packages/pandas/io/formats/format.py", line 1105, in to_csv
    csv_formatter.save()
  File "/home/airflow/.local/lib/python3.7/site-packages/pandas/io/formats/csvs.py", line 243, in save
    storage_options=self.storage_options,
  File "/home/airflow/.local/lib/python3.7/site-packages/pandas/io/common.py", line 707, in get_handle
    newline="",
FileNotFoundError: [Errno 2] No such file or directory: '/usr/local/airflow/data/1670114363_weather_api.csv'
[2022-12-04T00:39:23.879+0000] {taskinstance.py:1406} INFO - Marking task as FAILED. dag_id=extract_dag, task_id=extract_weather_api, execution_date=20221202T201500, start_date=20221204T003923, end_date=20221204T003923
[2022-12-04T00:39:23.891+0000] {warnings.py:110} WARNING - /home/***/.local/lib/python3.7/site-packages/***/utils/email.py:120: RemovedInAirflow3Warning: Fetching SMTP credentials from configuration variables will be deprecated in a future release. Please set credentials using a connection instead.
  send_mime_email(e_from=mail_from, e_to=recipients, mime_msg=msg, conn_id=conn_id, dryrun=dryrun)

[2022-12-04T00:39:23.892+0000] {configuration.py:569} WARNING - section/key [smtp/smtp_user] not found in config
[2022-12-04T00:39:23.894+0000] {email.py:229} INFO - Email alerting: attempt 1
[2022-12-04T00:39:23.902+0000] {configuration.py:569} WARNING - section/key [smtp/smtp_user] not found in config
[2022-12-04T00:39:23.904+0000] {email.py:229} INFO - Email alerting: attempt 1
[2022-12-04T00:39:23.905+0000] {taskinstance.py:1914} ERROR - Failed to send email to: ['***@***.com']
Traceback (most recent call last):
  File "/home/airflow/.local/lib/python3.7/site-packages/airflow/models/taskinstance.py", line 1457, in _run_raw_task
    self._execute_task_with_callbacks(context, test_mode)
  File "/home/airflow/.local/lib/python3.7/site-packages/airflow/models/taskinstance.py", line 1603, in _execute_task_with_callbacks
    result = self._execute_task(context, task_orig)
  File "/home/airflow/.local/lib/python3.7/site-packages/airflow/models/taskinstance.py", line 1664, in _execute_task
    result = execute_callable(context=context)
  File "/home/airflow/.local/lib/python3.7/site-packages/airflow/operators/python.py", line 175, in execute
    return_value = self.execute_callable()
  File "/home/airflow/.local/lib/python3.7/site-packages/airflow/operators/python.py", line 193, in execute_callable
    return self.python_callable(*self.op_args, **self.op_kwargs)
  File "/opt/airflow/dags/extract_dag.py", line 37, in extract_func
    df.to_csv(f'/usr/local/airflow/data/{col_name}_weather_api.csv',index=False)
  File "/home/airflow/.local/lib/python3.7/site-packages/pandas/core/generic.py", line 3482, in to_csv
    storage_options=storage_options,
  File "/home/airflow/.local/lib/python3.7/site-packages/pandas/io/formats/format.py", line 1105, in to_csv
    csv_formatter.save()
  File "/home/airflow/.local/lib/python3.7/site-packages/pandas/io/formats/csvs.py", line 243, in save
    storage_options=self.storage_options,
  File "/home/airflow/.local/lib/python3.7/site-packages/pandas/io/common.py", line 707, in get_handle
    newline="",
FileNotFoundError: [Errno 2] No such file or directory: '/usr/local/airflow/data/1670114363_weather_api.csv'

During handling of the above exception, another exception occurred:

Traceback (most recent call last):
  File "/home/airflow/.local/lib/python3.7/site-packages/airflow/models/taskinstance.py", line 2315, in email_alert
    send_email(task.email, subject, html_content)
  File "/home/airflow/.local/lib/python3.7/site-packages/airflow/utils/email.py", line 72, in send_email
    **kwargs,
  File "/home/airflow/.local/lib/python3.7/site-packages/airflow/utils/email.py", line 120, in send_email_smtp
    send_mime_email(e_from=mail_from, e_to=recipients, mime_msg=msg, conn_id=conn_id, dryrun=dryrun)
  File "/home/airflow/.local/lib/python3.7/site-packages/airflow/utils/email.py", line 231, in send_mime_email
    smtp_conn = _get_smtp_connection(smtp_host, smtp_port, smtp_timeout, smtp_ssl)
  File "/home/airflow/.local/lib/python3.7/site-packages/airflow/utils/email.py", line 265, in _get_smtp_connection
    else smtplib.SMTP(host=host, port=port, timeout=timeout)
  File "/usr/local/lib/python3.7/smtplib.py", line 251, in __init__
    (code, msg) = self.connect(host, port)
  File "/usr/local/lib/python3.7/smtplib.py", line 336, in connect
    self.sock = self._get_socket(host, port, self.timeout)
  File "/usr/local/lib/python3.7/smtplib.py", line 307, in _get_socket
    self.source_address)
  File "/usr/local/lib/python3.7/socket.py", line 728, in create_connection
    raise err
  File "/usr/local/lib/python3.7/socket.py", line 716, in create_connection
    sock.connect(sa)
OSError: [Errno 99] Cannot assign requested address

During handling of the above exception, another exception occurred:

Traceback (most recent call last):
  File "/home/airflow/.local/lib/python3.7/site-packages/airflow/models/taskinstance.py", line 1912, in handle_failure
    self.email_alert(error, task)
  File "/home/airflow/.local/lib/python3.7/site-packages/airflow/models/taskinstance.py", line 2317, in email_alert
    send_email(task.email, subject, html_content_err)
  File "/home/airflow/.local/lib/python3.7/site-packages/airflow/utils/email.py", line 72, in send_email
    **kwargs,
  File "/home/airflow/.local/lib/python3.7/site-packages/airflow/utils/email.py", line 120, in send_email_smtp
    send_mime_email(e_from=mail_from, e_to=recipients, mime_msg=msg, conn_id=conn_id, dryrun=dryrun)
  File "/home/airflow/.local/lib/python3.7/site-packages/airflow/utils/email.py", line 231, in send_mime_email
    smtp_conn = _get_smtp_connection(smtp_host, smtp_port, smtp_timeout, smtp_ssl)
  File "/home/airflow/.local/lib/python3.7/site-packages/airflow/utils/email.py", line 265, in _get_smtp_connection
    else smtplib.SMTP(host=host, port=port, timeout=timeout)
  File "/usr/local/lib/python3.7/smtplib.py", line 251, in __init__
    (code, msg) = self.connect(host, port)
  File "/usr/local/lib/python3.7/smtplib.py", line 336, in connect
    self.sock = self._get_socket(host, port, self.timeout)
  File "/usr/local/lib/python3.7/smtplib.py", line 307, in _get_socket
    self.source_address)
  File "/usr/local/lib/python3.7/socket.py", line 728, in create_connection
    raise err
  File "/usr/local/lib/python3.7/socket.py", line 716, in create_connection
    sock.connect(sa)
OSError: [Errno 99] Cannot assign requested address
[2022-12-04T00:39:23.920+0000] {standard_task_runner.py:105} ERROR - Failed to execute job 10 for task extract_weather_api ([Errno 2] No such file or directory: '/usr/local/airflow/data/1670114363_weather_api.csv'; 60)
[2022-12-04T00:39:23.955+0000] {local_task_job.py:164} INFO - Task exited with return code 1
[2022-12-04T00:39:24.002+0000] {local_task_job.py:273} INFO - 0 downstream tasks scheduled from follow-on schedule check
