[2022-12-03T08:31:57.233+0000] {taskinstance.py:1165} INFO - Dependencies all met for <TaskInstance: extract_dag.extract_weather_api manual__2022-12-03T08:31:56.312378+00:00 [queued]>
[2022-12-03T08:31:57.239+0000] {taskinstance.py:1165} INFO - Dependencies all met for <TaskInstance: extract_dag.extract_weather_api manual__2022-12-03T08:31:56.312378+00:00 [queued]>
[2022-12-03T08:31:57.240+0000] {taskinstance.py:1362} INFO - 
--------------------------------------------------------------------------------
[2022-12-03T08:31:57.241+0000] {taskinstance.py:1363} INFO - Starting attempt 1 of 1
[2022-12-03T08:31:57.241+0000] {taskinstance.py:1364} INFO - 
--------------------------------------------------------------------------------
[2022-12-03T08:31:57.248+0000] {taskinstance.py:1383} INFO - Executing <Task(BashOperator): extract_weather_api> on 2022-12-03 08:31:56.312378+00:00
[2022-12-03T08:31:57.263+0000] {standard_task_runner.py:55} INFO - Started process 3983 to run task
[2022-12-03T08:31:57.268+0000] {standard_task_runner.py:82} INFO - Running: ['***', 'tasks', 'run', 'extract_dag', 'extract_weather_api', 'manual__2022-12-03T08:31:56.312378+00:00', '--job-id', '6', '--raw', '--subdir', 'DAGS_FOLDER/extract_dag.py', '--cfg-path', '/tmp/tmppe64jquj']
[2022-12-03T08:31:57.269+0000] {standard_task_runner.py:83} INFO - Job 6: Subtask extract_weather_api
[2022-12-03T08:31:57.313+0000] {task_command.py:376} INFO - Running <TaskInstance: extract_dag.extract_weather_api manual__2022-12-03T08:31:56.312378+00:00 [running]> on host 71f73f624e90
[2022-12-03T08:31:57.361+0000] {taskinstance.py:1592} INFO - Exporting the following env vars:
AIRFLOW_CTX_DAG_EMAIL=***@***.com
AIRFLOW_CTX_DAG_OWNER=***
AIRFLOW_CTX_DAG_ID=extract_dag
AIRFLOW_CTX_TASK_ID=extract_weather_api
AIRFLOW_CTX_EXECUTION_DATE=2022-12-03T08:31:56.312378+00:00
AIRFLOW_CTX_TRY_NUMBER=1
AIRFLOW_CTX_DAG_RUN_ID=manual__2022-12-03T08:31:56.312378+00:00
[2022-12-03T08:31:57.363+0000] {subprocess.py:63} INFO - Tmp dir root location: 
 /tmp
[2022-12-03T08:31:57.364+0000] {subprocess.py:75} INFO - Running command: ['/bin/bash', '-c', 'python includes/extract.py']
[2022-12-03T08:31:57.378+0000] {subprocess.py:86} INFO - Output:
[2022-12-03T08:31:57.437+0000] {subprocess.py:93} INFO - python: can't open file 'includes/extract.py': [Errno 2] No such file or directory
[2022-12-03T08:31:57.440+0000] {subprocess.py:97} INFO - Command exited with return code 2
[2022-12-03T08:31:57.451+0000] {taskinstance.py:1851} ERROR - Task failed with exception
Traceback (most recent call last):
  File "/home/airflow/.local/lib/python3.7/site-packages/airflow/operators/bash.py", line 197, in execute
    f'Bash command failed. The command returned a non-zero exit code {result.exit_code}.'
airflow.exceptions.AirflowException: Bash command failed. The command returned a non-zero exit code 2.
[2022-12-03T08:31:57.454+0000] {taskinstance.py:1406} INFO - Marking task as FAILED. dag_id=extract_dag, task_id=extract_weather_api, execution_date=20221203T083156, start_date=20221203T083157, end_date=20221203T083157
[2022-12-03T08:31:57.466+0000] {warnings.py:110} WARNING - /home/***/.local/lib/python3.7/site-packages/***/utils/email.py:120: RemovedInAirflow3Warning: Fetching SMTP credentials from configuration variables will be deprecated in a future release. Please set credentials using a connection instead.
  send_mime_email(e_from=mail_from, e_to=recipients, mime_msg=msg, conn_id=conn_id, dryrun=dryrun)

[2022-12-03T08:31:57.467+0000] {configuration.py:569} WARNING - section/key [smtp/smtp_user] not found in config
[2022-12-03T08:31:57.468+0000] {email.py:229} INFO - Email alerting: attempt 1
[2022-12-03T08:31:57.473+0000] {configuration.py:569} WARNING - section/key [smtp/smtp_user] not found in config
[2022-12-03T08:31:57.474+0000] {email.py:229} INFO - Email alerting: attempt 1
[2022-12-03T08:31:57.475+0000] {taskinstance.py:1914} ERROR - Failed to send email to: ['***@***.com']
Traceback (most recent call last):
  File "/home/airflow/.local/lib/python3.7/site-packages/airflow/models/taskinstance.py", line 1457, in _run_raw_task
    self._execute_task_with_callbacks(context, test_mode)
  File "/home/airflow/.local/lib/python3.7/site-packages/airflow/models/taskinstance.py", line 1603, in _execute_task_with_callbacks
    result = self._execute_task(context, task_orig)
  File "/home/airflow/.local/lib/python3.7/site-packages/airflow/models/taskinstance.py", line 1664, in _execute_task
    result = execute_callable(context=context)
  File "/home/airflow/.local/lib/python3.7/site-packages/airflow/operators/bash.py", line 197, in execute
    f'Bash command failed. The command returned a non-zero exit code {result.exit_code}.'
airflow.exceptions.AirflowException: Bash command failed. The command returned a non-zero exit code 2.

During handling of the above exception, another exception occurred:

Traceback (most recent call last):
  File "/home/airflow/.local/lib/python3.7/site-packages/airflow/models/taskinstance.py", line 2315, in email_alert
    send_email(task.email, subject, html_content)
  File "/home/airflow/.local/lib/python3.7/site-packages/airflow/utils/email.py", line 72, in send_email
    **kwargs,
  File "/home/airflow/.local/lib/python3.7/site-packages/airflow/utils/email.py", line 120, in send_email_smtp
    send_mime_email(e_from=mail_from, e_to=recipients, mime_msg=msg, conn_id=conn_id, dryrun=dryrun)
  File "/home/airflow/.local/lib/python3.7/site-packages/airflow/utils/email.py", line 231, in send_mime_email
    smtp_conn = _get_smtp_connection(smtp_host, smtp_port, smtp_timeout, smtp_ssl)
  File "/home/airflow/.local/lib/python3.7/site-packages/airflow/utils/email.py", line 265, in _get_smtp_connection
    else smtplib.SMTP(host=host, port=port, timeout=timeout)
  File "/usr/local/lib/python3.7/smtplib.py", line 251, in __init__
    (code, msg) = self.connect(host, port)
  File "/usr/local/lib/python3.7/smtplib.py", line 336, in connect
    self.sock = self._get_socket(host, port, self.timeout)
  File "/usr/local/lib/python3.7/smtplib.py", line 307, in _get_socket
    self.source_address)
  File "/usr/local/lib/python3.7/socket.py", line 728, in create_connection
    raise err
  File "/usr/local/lib/python3.7/socket.py", line 716, in create_connection
    sock.connect(sa)
OSError: [Errno 99] Cannot assign requested address

During handling of the above exception, another exception occurred:

Traceback (most recent call last):
  File "/home/airflow/.local/lib/python3.7/site-packages/airflow/models/taskinstance.py", line 1912, in handle_failure
    self.email_alert(error, task)
  File "/home/airflow/.local/lib/python3.7/site-packages/airflow/models/taskinstance.py", line 2317, in email_alert
    send_email(task.email, subject, html_content_err)
  File "/home/airflow/.local/lib/python3.7/site-packages/airflow/utils/email.py", line 72, in send_email
    **kwargs,
  File "/home/airflow/.local/lib/python3.7/site-packages/airflow/utils/email.py", line 120, in send_email_smtp
    send_mime_email(e_from=mail_from, e_to=recipients, mime_msg=msg, conn_id=conn_id, dryrun=dryrun)
  File "/home/airflow/.local/lib/python3.7/site-packages/airflow/utils/email.py", line 231, in send_mime_email
    smtp_conn = _get_smtp_connection(smtp_host, smtp_port, smtp_timeout, smtp_ssl)
  File "/home/airflow/.local/lib/python3.7/site-packages/airflow/utils/email.py", line 265, in _get_smtp_connection
    else smtplib.SMTP(host=host, port=port, timeout=timeout)
  File "/usr/local/lib/python3.7/smtplib.py", line 251, in __init__
    (code, msg) = self.connect(host, port)
  File "/usr/local/lib/python3.7/smtplib.py", line 336, in connect
    self.sock = self._get_socket(host, port, self.timeout)
  File "/usr/local/lib/python3.7/smtplib.py", line 307, in _get_socket
    self.source_address)
  File "/usr/local/lib/python3.7/socket.py", line 728, in create_connection
    raise err
  File "/usr/local/lib/python3.7/socket.py", line 716, in create_connection
    sock.connect(sa)
OSError: [Errno 99] Cannot assign requested address
[2022-12-03T08:31:57.485+0000] {standard_task_runner.py:105} ERROR - Failed to execute job 6 for task extract_weather_api (Bash command failed. The command returned a non-zero exit code 2.; 3983)
[2022-12-03T08:31:57.526+0000] {local_task_job.py:164} INFO - Task exited with return code 1
[2022-12-03T08:31:57.543+0000] {local_task_job.py:273} INFO - 0 downstream tasks scheduled from follow-on schedule check
