[2022-12-03T19:26:53.894+0000] {taskinstance.py:1165} INFO - Dependencies all met for <TaskInstance: extract_dag.extract_weather_api manual__2022-12-03T19:26:52.843336+00:00 [queued]>
[2022-12-03T19:26:53.902+0000] {taskinstance.py:1165} INFO - Dependencies all met for <TaskInstance: extract_dag.extract_weather_api manual__2022-12-03T19:26:52.843336+00:00 [queued]>
[2022-12-03T19:26:53.903+0000] {taskinstance.py:1362} INFO - 
--------------------------------------------------------------------------------
[2022-12-03T19:26:53.903+0000] {taskinstance.py:1363} INFO - Starting attempt 1 of 1
[2022-12-03T19:26:53.903+0000] {taskinstance.py:1364} INFO - 
--------------------------------------------------------------------------------
[2022-12-03T19:26:53.911+0000] {taskinstance.py:1383} INFO - Executing <Task(PythonOperator): extract_weather_api> on 2022-12-03 19:26:52.843336+00:00
[2022-12-03T19:26:53.915+0000] {standard_task_runner.py:55} INFO - Started process 666 to run task
[2022-12-03T19:26:53.919+0000] {standard_task_runner.py:82} INFO - Running: ['***', 'tasks', 'run', 'extract_dag', 'extract_weather_api', 'manual__2022-12-03T19:26:52.843336+00:00', '--job-id', '7', '--raw', '--subdir', 'DAGS_FOLDER/extract_dag.py', '--cfg-path', '/tmp/tmp5eev6ou4']
[2022-12-03T19:26:53.921+0000] {standard_task_runner.py:83} INFO - Job 7: Subtask extract_weather_api
[2022-12-03T19:26:53.971+0000] {task_command.py:376} INFO - Running <TaskInstance: extract_dag.extract_weather_api manual__2022-12-03T19:26:52.843336+00:00 [running]> on host 3886eb57bcb4
[2022-12-03T19:26:54.012+0000] {taskinstance.py:1592} INFO - Exporting the following env vars:
AIRFLOW_CTX_DAG_EMAIL=***@***.com
AIRFLOW_CTX_DAG_OWNER=***
AIRFLOW_CTX_DAG_ID=extract_dag
AIRFLOW_CTX_TASK_ID=extract_weather_api
AIRFLOW_CTX_EXECUTION_DATE=2022-12-03T19:26:52.843336+00:00
AIRFLOW_CTX_TRY_NUMBER=1
AIRFLOW_CTX_DAG_RUN_ID=manual__2022-12-03T19:26:52.843336+00:00
[2022-12-03T19:26:54.321+0000] {taskinstance.py:1851} ERROR - Task failed with exception
Traceback (most recent call last):
  File "/home/airflow/.local/lib/python3.7/site-packages/airflow/operators/python.py", line 175, in execute
    return_value = self.execute_callable()
  File "/home/airflow/.local/lib/python3.7/site-packages/airflow/operators/python.py", line 193, in execute_callable
    return self.python_callable(*self.op_args, **self.op_kwargs)
  File "/opt/airflow/dags/extract_dag.py", line 37, in extract_func
    df.to_csv(f'/usr/local/airflow/data/{col_name}_weather_api.csv',index=False)
  File "/home/airflow/.local/lib/python3.7/site-packages/pandas/core/generic.py", line 3482, in to_csv
    storage_options=storage_options,
  File "/home/airflow/.local/lib/python3.7/site-packages/pandas/io/formats/format.py", line 1105, in to_csv
    csv_formatter.save()
  File "/home/airflow/.local/lib/python3.7/site-packages/pandas/io/formats/csvs.py", line 243, in save
    storage_options=self.storage_options,
  File "/home/airflow/.local/lib/python3.7/site-packages/pandas/io/common.py", line 707, in get_handle
    newline="",
FileNotFoundError: [Errno 2] No such file or directory: '/usr/local/airflow/data/1670095618_weather_api.csv'
[2022-12-03T19:26:54.336+0000] {taskinstance.py:1406} INFO - Marking task as FAILED. dag_id=extract_dag, task_id=extract_weather_api, execution_date=20221203T192652, start_date=20221203T192653, end_date=20221203T192654
[2022-12-03T19:26:54.347+0000] {warnings.py:110} WARNING - /home/***/.local/lib/python3.7/site-packages/***/utils/email.py:120: RemovedInAirflow3Warning: Fetching SMTP credentials from configuration variables will be deprecated in a future release. Please set credentials using a connection instead.
  send_mime_email(e_from=mail_from, e_to=recipients, mime_msg=msg, conn_id=conn_id, dryrun=dryrun)

[2022-12-03T19:26:54.347+0000] {configuration.py:569} WARNING - section/key [smtp/smtp_user] not found in config
[2022-12-03T19:26:54.348+0000] {email.py:229} INFO - Email alerting: attempt 1
[2022-12-03T19:26:54.355+0000] {configuration.py:569} WARNING - section/key [smtp/smtp_user] not found in config
[2022-12-03T19:26:54.356+0000] {email.py:229} INFO - Email alerting: attempt 1
[2022-12-03T19:26:54.357+0000] {taskinstance.py:1914} ERROR - Failed to send email to: ['***@***.com']
Traceback (most recent call last):
  File "/home/airflow/.local/lib/python3.7/site-packages/airflow/models/taskinstance.py", line 1457, in _run_raw_task
    self._execute_task_with_callbacks(context, test_mode)
  File "/home/airflow/.local/lib/python3.7/site-packages/airflow/models/taskinstance.py", line 1603, in _execute_task_with_callbacks
    result = self._execute_task(context, task_orig)
  File "/home/airflow/.local/lib/python3.7/site-packages/airflow/models/taskinstance.py", line 1664, in _execute_task
    result = execute_callable(context=context)
  File "/home/airflow/.local/lib/python3.7/site-packages/airflow/operators/python.py", line 175, in execute
    return_value = self.execute_callable()
  File "/home/airflow/.local/lib/python3.7/site-packages/airflow/operators/python.py", line 193, in execute_callable
    return self.python_callable(*self.op_args, **self.op_kwargs)
  File "/opt/airflow/dags/extract_dag.py", line 37, in extract_func
    df.to_csv(f'/usr/local/airflow/data/{col_name}_weather_api.csv',index=False)
  File "/home/airflow/.local/lib/python3.7/site-packages/pandas/core/generic.py", line 3482, in to_csv
    storage_options=storage_options,
  File "/home/airflow/.local/lib/python3.7/site-packages/pandas/io/formats/format.py", line 1105, in to_csv
    csv_formatter.save()
  File "/home/airflow/.local/lib/python3.7/site-packages/pandas/io/formats/csvs.py", line 243, in save
    storage_options=self.storage_options,
  File "/home/airflow/.local/lib/python3.7/site-packages/pandas/io/common.py", line 707, in get_handle
    newline="",
FileNotFoundError: [Errno 2] No such file or directory: '/usr/local/airflow/data/1670095618_weather_api.csv'

During handling of the above exception, another exception occurred:

Traceback (most recent call last):
  File "/home/airflow/.local/lib/python3.7/site-packages/airflow/models/taskinstance.py", line 2315, in email_alert
    send_email(task.email, subject, html_content)
  File "/home/airflow/.local/lib/python3.7/site-packages/airflow/utils/email.py", line 72, in send_email
    **kwargs,
  File "/home/airflow/.local/lib/python3.7/site-packages/airflow/utils/email.py", line 120, in send_email_smtp
    send_mime_email(e_from=mail_from, e_to=recipients, mime_msg=msg, conn_id=conn_id, dryrun=dryrun)
  File "/home/airflow/.local/lib/python3.7/site-packages/airflow/utils/email.py", line 231, in send_mime_email
    smtp_conn = _get_smtp_connection(smtp_host, smtp_port, smtp_timeout, smtp_ssl)
  File "/home/airflow/.local/lib/python3.7/site-packages/airflow/utils/email.py", line 265, in _get_smtp_connection
    else smtplib.SMTP(host=host, port=port, timeout=timeout)
  File "/usr/local/lib/python3.7/smtplib.py", line 251, in __init__
    (code, msg) = self.connect(host, port)
  File "/usr/local/lib/python3.7/smtplib.py", line 336, in connect
    self.sock = self._get_socket(host, port, self.timeout)
  File "/usr/local/lib/python3.7/smtplib.py", line 307, in _get_socket
    self.source_address)
  File "/usr/local/lib/python3.7/socket.py", line 728, in create_connection
    raise err
  File "/usr/local/lib/python3.7/socket.py", line 716, in create_connection
    sock.connect(sa)
OSError: [Errno 99] Cannot assign requested address

During handling of the above exception, another exception occurred:

Traceback (most recent call last):
  File "/home/airflow/.local/lib/python3.7/site-packages/airflow/models/taskinstance.py", line 1912, in handle_failure
    self.email_alert(error, task)
  File "/home/airflow/.local/lib/python3.7/site-packages/airflow/models/taskinstance.py", line 2317, in email_alert
    send_email(task.email, subject, html_content_err)
  File "/home/airflow/.local/lib/python3.7/site-packages/airflow/utils/email.py", line 72, in send_email
    **kwargs,
  File "/home/airflow/.local/lib/python3.7/site-packages/airflow/utils/email.py", line 120, in send_email_smtp
    send_mime_email(e_from=mail_from, e_to=recipients, mime_msg=msg, conn_id=conn_id, dryrun=dryrun)
  File "/home/airflow/.local/lib/python3.7/site-packages/airflow/utils/email.py", line 231, in send_mime_email
    smtp_conn = _get_smtp_connection(smtp_host, smtp_port, smtp_timeout, smtp_ssl)
  File "/home/airflow/.local/lib/python3.7/site-packages/airflow/utils/email.py", line 265, in _get_smtp_connection
    else smtplib.SMTP(host=host, port=port, timeout=timeout)
  File "/usr/local/lib/python3.7/smtplib.py", line 251, in __init__
    (code, msg) = self.connect(host, port)
  File "/usr/local/lib/python3.7/smtplib.py", line 336, in connect
    self.sock = self._get_socket(host, port, self.timeout)
  File "/usr/local/lib/python3.7/smtplib.py", line 307, in _get_socket
    self.source_address)
  File "/usr/local/lib/python3.7/socket.py", line 728, in create_connection
    raise err
  File "/usr/local/lib/python3.7/socket.py", line 716, in create_connection
    sock.connect(sa)
OSError: [Errno 99] Cannot assign requested address
[2022-12-03T19:26:54.371+0000] {standard_task_runner.py:105} ERROR - Failed to execute job 7 for task extract_weather_api ([Errno 2] No such file or directory: '/usr/local/airflow/data/1670095618_weather_api.csv'; 666)
[2022-12-03T19:26:54.422+0000] {local_task_job.py:164} INFO - Task exited with return code 1
[2022-12-03T19:26:54.448+0000] {local_task_job.py:273} INFO - 0 downstream tasks scheduled from follow-on schedule check
